{
 "cells": [
  {
   "cell_type": "markdown",
   "id": "bb65c627-0700-46ba-9296-f29532f6af87",
   "metadata": {},
   "source": [
    "### Q1. What is the role of try and exception block?\n",
    "\n",
    "**Answer:**\n",
    "\n",
    "In Python, the `try` and `except` blocks are used for handling exceptions or errors that might occur during the execution of code. Here's how they work:\n",
    "\n",
    "- Try Block: The try block contains the code where you anticipate an error might occur. It's the section of code that you want to monitor for exceptions.\n",
    "\n",
    "- Except Block: The except block is executed if an exception occurs within the try block. It allows you to handle specific types of exceptions or all exceptions in a generic way. You can specify the type of exception you're expecting to catch, or use a more general except block to catch any type of exception.\n",
    "\n",
    "Example:\n",
    "```python\n",
    "try:\n",
    "    # Code that might cause an exception\n",
    "    result = 10 / 0  # This will raise a ZeroDivisionError\n",
    "    print(result)   # This line won't be executed if an exception occurs\n",
    "except ZeroDivisionError:\n",
    "    # Handle the specific exception (ZeroDivisionError in this case)\n",
    "    print(\"Error: Division by zero\")\n",
    "except Exception as e:\n",
    "    # Catch any other exception\n",
    "    print(f\"An error occurred: {e}\")\n",
    "```\n",
    "\n",
    "In this example:\n",
    "\n",
    "- The code inside the `try` block attempts to divide 10 by 0, which raises a `ZeroDivisionError`.\n",
    "- As a result, the program jumps to the `except ZeroDivisionError` block and executes the code there, printing \"Error: Division by zero.\"\n",
    "\n",
    "\n",
    "Using `try` and `except` blocks helps in gracefully handling errors and prevents the program from crashing abruptly. It allows you to respond to errors in a way that makes sense for your application, whether that's logging the error, providing a default value, or prompting the user for different input."
   ]
  },
  {
   "cell_type": "markdown",
   "id": "4175a872-37e7-41a3-9189-23ac2c11b482",
   "metadata": {},
   "source": [
    "### Q2. What is the syntax for a basic try-except block?\n",
    "\n",
    "**Answer:**\n",
    "\n",
    "Here's the basic syntax for a try-except block in Python:\n",
    "\n",
    "```python\n",
    "try:\n",
    "    # Code that might raise an exception\n",
    "    # ...\n",
    "except SomeException:\n",
    "    # Code to handle the specific exception (replace SomeException with the type of exception)\n",
    "    # ...\n",
    "except AnotherException as e:\n",
    "    # Code to handle another specific exception, with access to the exception object (e)\n",
    "    # ...\n",
    "except:\n",
    "    # Code to handle any other exception (this is a catch-all for any exception)\n",
    "    # ...\n",
    "else:\n",
    "    # Optional block that runs if no exceptions were raised in the try block\n",
    "    # ...\n",
    "finally:\n",
    "    # Optional block that always runs, regardless of whether an exception was raised or not\n",
    "    # ...\n",
    "```\n",
    "\n",
    "- `try`: This is where we place the code that might raise an exception.\n",
    "\n",
    "- `except`: We can have one or more except blocks immediately following the try block. Each except block handles a specific type of exception. If that type of exception occurs in the try block, the corresponding except block is executed.\n",
    "\n",
    "- `else` (optional): This block is executed if no exceptions occur in the try block. It's not required and is often omitted.\n",
    "\n",
    "- `finally` (optional): This block is always executed, regardless of whether an exception was raised or not. It's commonly used for cleanup actions (closing files, releasing resources, etc.).\n",
    "\n",
    "We can use specific exception types (like `ValueError`, `TypeError`, `ZeroDivisionError`, etc.) or a more generic except block without specifying an exception type to catch any exception that wasn't caught by the preceding except blocks."
   ]
  },
  {
   "cell_type": "markdown",
   "id": "3ed2e20a-e76c-4f31-a5c9-771d3a7f0011",
   "metadata": {},
   "source": [
    "### Q3. What happens if an exception occurs inside a try block and there is no matching except block?\n",
    "\n",
    "**Answer:**\n",
    "\n",
    "\n",
    "If an exception occurs inside a `try` block and there is no matching `except` block to handle that specific type of exception, the exception propagates up the call stack. If unhandled, it eventually leads to the termination of the program and displays an error message (called an unhandled exception traceback).\n",
    "\n",
    "When there's no appropriate `except` block to catch a specific exception raised within the `try` block, the program's normal flow is disrupted, and Python will look for exception handling further up in the call stack. If no suitable handler is found at any level, Python's default behavior is to display an error message detailing the exception traceback, showing where the exception occurred along with the type of exception and the call stack."
   ]
  },
  {
   "cell_type": "markdown",
   "id": "0769a41f-e2df-45ed-9eb9-488f15182698",
   "metadata": {},
   "source": [
    "### Q4. What is the difference between using a bare except block and specifying a specific exception type?\n",
    "\n",
    "**Answer:**\n",
    "\n",
    "Using a bare `except` block (except:) and specifying a specific exception type (except SomeException:) have distinct differences in how they handle exceptions in Python:\n",
    "\n",
    "1. Specific Exception Type (except SomeException:):\n",
    "\n",
    "- When we specify a particular exception type (like `except ValueError`: or `except FileNotFoundError`:), we're explicitly catching that specific type of exception.\n",
    "- It allows us to handle different types of exceptions differently, providing tailored responses or error handling strategies based on the type of exception caught.\n",
    "- Using specific exception types is generally considered good practice because it helps in creating more targeted and controlled exception handling.\n",
    "\n",
    "2. Bare `Except` Block (except:):\n",
    "\n",
    "- A bare `except` block catches any exception that was not caught by previous except blocks higher in the hierarchy.\n",
    "- It doesn't distinguish between different types of exceptions; it catches all exceptions, including system-exiting exceptions like SystemExit or KeyboardInterrupt.\n",
    "- Using a bare `except` block can make it harder to diagnose and debug issues because it catches all exceptions, potentially hiding errors that should be handled differently.\n",
    "- It's generally recommended to avoid using bare except blocks in most cases, as they can mask errors and make troubleshooting more challenging.\n",
    "\n",
    "Example:\n",
    "```python\n",
    "# Specific exception handling\n",
    "try:\n",
    "    result = int(\"abc\")  # This raises a ValueError\n",
    "except ValueError:\n",
    "    print(\"ValueError occurred\")\n",
    "\n",
    "# Bare except block\n",
    "try:\n",
    "    result = 10 / 0  # This raises a ZeroDivisionError\n",
    "except:\n",
    "    print(\"Some error occurred\")\n",
    "```\n",
    "\n",
    "In the first case, only a `ValueError` will trigger the specific handling code. In the second case, any error, regardless of its type, will trigger the generic error handling code.\n",
    "\n",
    "Using specific exception handling provides more control and clarity in handling different types of exceptions, making our code more robust and maintainable."
   ]
  },
  {
   "cell_type": "markdown",
   "id": "5f733c7c-3349-40df-8232-e2c9257fcdbc",
   "metadata": {},
   "source": [
    "### Q5. Can you have nested try-except blocks in Python? If yes, then give an example.\n",
    "\n",
    "**Answer:** \n",
    "\n",
    "Yes, we can have nested try-except blocks in Python. This means placing one try-except block inside another try block's try or except block.\n",
    "\n",
    "Here's an example demonstrating nested try-except blocks:"
   ]
  },
  {
   "cell_type": "code",
   "execution_count": 1,
   "id": "eee9254b-b2c6-41c9-9af5-53c55a7d9586",
   "metadata": {},
   "outputs": [
    {
     "name": "stdout",
     "output_type": "stream",
     "text": [
      "Enter a number: 10\n",
      "Result of division: 1.0\n",
      "Enter a string: push\n",
      "Length of the string: 4\n"
     ]
    }
   ],
   "source": [
    "try:\n",
    "    # Outer try block\n",
    "    num = int(input(\"Enter a number: \"))\n",
    "    \n",
    "    try:\n",
    "        # Inner try block\n",
    "        result = 10 / num\n",
    "        print(\"Result of division:\", result)\n",
    "    \n",
    "    except ZeroDivisionError:\n",
    "        # Inner except block handling ZeroDivisionError\n",
    "        print(\"Cannot divide by zero in inner block\")\n",
    "    \n",
    "    # Some other code in the outer try block\n",
    "    string = input(\"Enter a string: \")\n",
    "    print(\"Length of the string:\", len(string))\n",
    "\n",
    "except ValueError:\n",
    "    # Outer except block handling ValueError\n",
    "    print(\"Please enter a valid number\")\n",
    "\n",
    "except Exception as e:\n",
    "    # Outer except block handling any other exception\n",
    "    print(\"An error occurred:\", e)\n"
   ]
  },
  {
   "cell_type": "markdown",
   "id": "ade5f753",
   "metadata": {},
   "source": [
    "In above example:\n",
    "\n",
    "- There's an outer `try-except` block that handles potential exceptions arising from converting user input to an integer (ValueError) or other exceptions.\n",
    "- Inside the outer `try` block, there's an inner `try-except` block that handles a potential `ZeroDivisionError` when performing division. It's nested within the outer `try` block.\n",
    "- The inner `try-except` block is only concerned with the division operation, while the outer `try-except` block covers the entire set of operations and input processes.\n",
    "\n",
    "Nested try-except blocks are useful for handling exceptions at different levels of granularity, allowing for more specific and controlled error handling within different parts of your code."
   ]
  },
  {
   "cell_type": "markdown",
   "id": "04804353-1792-49b6-8e3a-01ed271bffdf",
   "metadata": {},
   "source": [
    "## Q6. Can we use multiple exception blocks, if yes then give an example."
   ]
  },
  {
   "cell_type": "code",
   "execution_count": 2,
   "id": "4d03cea9-1211-451b-a476-feb6e1c8825a",
   "metadata": {},
   "outputs": [
    {
     "name": "stdout",
     "output_type": "stream",
     "text": [
      "Enter a number: 58\n",
      "Enter another number: 0\n",
      "Division by zero is not allowed.\n",
      "Execution completed.\n"
     ]
    }
   ],
   "source": [
    "try:\n",
    "    num1 = int(input(\"Enter a number: \"))\n",
    "    num2 = int(input(\"Enter another number: \"))\n",
    "    result = num1 / num2\n",
    "\n",
    "except ValueError:\n",
    "    print(\"Invalid input. Please enter valid numbers.\")\n",
    "\n",
    "except ZeroDivisionError:\n",
    "    print(\"Division by zero is not allowed.\")\n",
    "\n",
    "except Exception as e:\n",
    "    print(f\"An error occurred: {e}\")\n",
    "\n",
    "else:\n",
    "    print(f\"The result is: {result}\")\n",
    "\n",
    "finally:\n",
    "    print(\"Execution completed.\")\n"
   ]
  },
  {
   "cell_type": "markdown",
   "id": "b1cd486f-a47e-46fd-a801-3dafba0f8427",
   "metadata": {},
   "source": [
    "### Q7. Write the reason due to which following errors are raised.\n",
    "\n",
    "**Answer:**\n",
    "\n",
    "Here are the reasons due to which the mentioned errors are raised:\n",
    "\n",
    "a. `EOFError`: This error is raised when an input operation (e.g., `input()`) reaches the end of a file or input stream unexpectedly. It typically occurs when trying to read more data than is available.\n",
    "\n",
    "b. `FloatingPointError`: This error occurs during floating-point arithmetic operations (e.g., division by zero or an invalid operation) when the result cannot be represented as a valid floating-point number.\n",
    "\n",
    "c. `IndexError`: This error is raised when you try to access an index that is outside the bounds of a sequence (e.g., a list or a string). It usually happens when trying to access an element beyond the range of valid indices.\n",
    "\n",
    "d. `MemoryError`: This error is raised when an operation attempts to allocate more memory than the system can provide, indicating that the system is out of memory resources.\n",
    "\n",
    "e. `OverflowError`: This error occurs during numerical operations when the result exceeds the maximum representable value for the data type in use. It typically occurs with integers.\n",
    "\n",
    "f. `TabError`: This error is raised when there are inconsistencies in the use of tabs and spaces for indentation in Python code, especially within the same block. Python expects consistent indentation to define code blocks.\n",
    "\n",
    "g. `ValueError`: This error is raised when an operation or function receives an argument of the correct data type but with an inappropriate or invalid value. It typically occurs when you pass an argument that is outside the expected range or does not make sense in the context of the operation.\n",
    "\n",
    "Understanding these error types helps in debugging and handling exceptions appropriately in Python programs."
   ]
  },
  {
   "cell_type": "markdown",
   "id": "b5ae05a3-4f17-4cd1-b2d2-fdb857f381fb",
   "metadata": {},
   "source": [
    "## Q8. Write code for the following given scenario and add try-exception block to it.\n",
    "a. Program to divide two numbers\n",
    "\n",
    "b. Program to convert a string to an integer\n",
    "\n",
    "c. Program to access an element in a list\n",
    "\n",
    "d. Program to handle a specific exception\n",
    "\n",
    "e. Program to handle any exception"
   ]
  },
  {
   "cell_type": "markdown",
   "id": "0027bb87-e65d-4256-ade8-4866e2df51d7",
   "metadata": {},
   "source": [
    "\n",
    "a. Program to divide two numbers:\n",
    "\n",
    "```python\n",
    "try:\n",
    "    num1 = float(input(\"Enter the first number: \"))\n",
    "    num2 = float(input(\"Enter the second number: \"))\n",
    "    result = num1 / num2\n",
    "    print(f\"The result of the division is: {result}\")\n",
    "\n",
    "except ZeroDivisionError:\n",
    "    print(\"Error: Division by zero is not allowed.\")\n",
    "\n",
    "except ValueError:\n",
    "    print(\"Error: Invalid input. Please enter valid numbers.\")\n",
    "```\n",
    "\n",
    "b. Program to convert a string to an integer:\n",
    "\n",
    "```python\n",
    "try:\n",
    "    input_str = input(\"Enter an integer: \")\n",
    "    num = int(input_str)\n",
    "    print(f\"Successfully converted to an integer: {num}\")\n",
    "\n",
    "except ValueError:\n",
    "    print(\"Error: Invalid input. Please enter a valid integer.\")\n",
    "```\n",
    "\n",
    "c. Program to access an element in a list:\n",
    "\n",
    "```python\n",
    "try:\n",
    "    my_list = [1, 2, 3, 4, 5]\n",
    "    index = int(input(\"Enter an index to access an element: \"))\n",
    "    value = my_list[index]\n",
    "    print(f\"The element at index {index} is: {value}\")\n",
    "\n",
    "except IndexError:\n",
    "    print(\"Error: Index out of range. Please enter a valid index.\")\n",
    "\n",
    "except ValueError:\n",
    "    print(\"Error: Invalid input. Please enter a valid integer as the index.\")\n",
    "```\n",
    "\n",
    "d. Program to handle a specific exception:\n",
    "\n",
    "```python\n",
    "try:\n",
    "    number = int(input(\"Enter a number: \"))\n",
    "    if number < 0:\n",
    "        raise ValueError(\"Negative numbers are not allowed.\")\n",
    "\n",
    "except ValueError as e:\n",
    "    print(f\"Error: {e}\")\n",
    "```\n",
    "\n",
    "e. Program to handle any exception:\n",
    "\n",
    "```python\n",
    "try:\n",
    "    result = 10 / 0  # This will raise a ZeroDivisionError\n",
    "    print(result)    # This line won't be executed due to the exception\n",
    "\n",
    "except Exception as e:\n",
    "    print(f\"An error occurred: {e}\")\n",
    "```\n",
    "\n",
    "These examples illustrate how try-except blocks can be used to handle various types of exceptions in different scenarios."
   ]
  }
 ],
 "metadata": {
  "kernelspec": {
   "display_name": "Python 3 (ipykernel)",
   "language": "python",
   "name": "python3"
  },
  "language_info": {
   "codemirror_mode": {
    "name": "ipython",
    "version": 3
   },
   "file_extension": ".py",
   "mimetype": "text/x-python",
   "name": "python",
   "nbconvert_exporter": "python",
   "pygments_lexer": "ipython3",
   "version": "3.11.5"
  }
 },
 "nbformat": 4,
 "nbformat_minor": 5
}
